<!-- Excavator model

This model implements a classic hydraulic excavator with functioning velocity
actuation and textured meshes.

Copyright, 2023, Vilella Kenny.
-->

<mujoco model="excavator" >
    <compiler meshdir="excavator/mesh" texturedir="excavator/texture"/>
  <visual>
    <headlight ambient="1 1 1" diffuse="0 0 0" specular="0 0 0"/>
  </visual>
  <asset>
    <mesh file="caterpillar.obj"/>
    <texture name="caterpillar" type="2d" file="caterpillar_texture.png"/>
    <material name="caterpillar" emission="1" texture="caterpillar"/>
    <mesh file="chassis.obj"/>
    <texture name="chassis" type="2d" file="chassis_texture.png"/>
    <material name="chassis" emission="1" texture="chassis"/>
    <mesh file="boom.obj"/>
    <texture name="boom" type="2d" file="boom_texture.png"/>
    <material name="boom" texture="boom" rgba="0.98 0.65 0.15 1"/>
    <mesh file="arm.obj" refquat="0.966 0 -0.259 0"/>
    <texture name="arm" type="2d" file="arm_texture.png"/>
    <material name="arm" texture="arm" rgba="0.98 0.65 0.15 1"/>
    <mesh file="bucket_refined.obj"/>
    <texture name="bucket" type="2d" file="bucket_texture.png"/>
    <material name="bucket" texture="bucket" rgba="0.3 0.3 0.3 1"/>
  </asset>
     <worldbody>
      <body name="caterpillar" pos="0 0 0.040" euler="0 0 0">
        <!--<joint type="free" limited='false' damping="0" stiffness="0" armature="0" frictionloss="6"/>-->
        <geom name="caterpillar" type="mesh" mesh="caterpillar" material="caterpillar" pos="0 0 0" euler="0 0 0"/>
        <inertial pos="0 0 0" mass="100.8" diaginertia="4.167 4.167 4.167"/>

        <body name="chassis" pos="0 0 0.767" euler="0 0 0">
          <joint name="chassis" type="hinge" axis="0 0 1" pos="0 0 0" frictionloss="120"/>
          <geom name="chassis" type="mesh" mesh="chassis" material="chassis" pos="0 0 0" euler="0 0 0"/>
          <inertial pos="0 0 0" mass="2" diaginertia=".002 .002 .002"/>

          <body name="boom" pos="0.326 0 0.389" euler="0 -30.0 0">
            <joint name="boom" type="hinge" axis="0 1 0" pos="0 0 0" frictionloss="100" stiffness="10"/>
            <geom name="boom" type="mesh" mesh="boom" material="boom" pos="0 0 0" euler="0 0 0"/>
            <inertial pos="1.729 0 0.463" mass=".33" diaginertia="0.00144107 0.00134228 0.000152047"/>

            <body name="arm" pos="3.945 0 -.55" euler="0 30.0 0">
              <joint name="arm" type="hinge" axis="0 1 0" pos="0 0 0" frictionloss="100" stiffness="10" />
              <geom name="arm" type="mesh" mesh="arm" material="arm" pos="0 0 0" euler="0 0 0"/>
              <inertial pos="0.476 0 0.119" mass=".415" diaginertia="0.0005911 0.000546493 0.000155707"/>
              <body name="bucket_top" pos="1.929 0 -0.998" euler="0 -30 0">
                <joint name="bucket_top" type="hinge" axis="0 1 0" pos="0 0 0" frictionloss="400"/>
                <geom name="bucket_top" type="mesh" mesh="bucket_refined" material="bucket" pos="0 0 0" euler="0 0 0" friction="10 .35 2.35" condim="6"/>
                <inertial pos="0 0 0" mass=".4" diaginertia="0.0005911 0.000546493 0.000155707"/>
                  <body name="bucket_top_grip" pos=".4 0 -.85" euler="0 0 0">
                      <geom name="bucket_top_grip" type="box" size=".04 .8 .04" material="boom" friction="10 .35 1" condim="6"/>
                      <inertial pos="0 0 0" mass=".115" diaginertia="5.45707e-05 4.63101e-05 4.32692e-05"/>
                  </body>
              </body> <!-- Bucket -->
              <body name="bucket_bottom" pos="1.729 0 -0.998" euler="0 -20 180">
                <joint name="bucket_bottom" type="hinge" axis="0 1 0" pos="0 0 0" frictionloss="400"/>
                <geom name="bucket_bottom" type="mesh" mesh="bucket_refined" material="bucket" pos="0 0 0" euler="0 0 0" friction="10 .35 2.35" condim="6"/>
                <inertial pos="0 0 0" mass=".4" diaginertia="0.0005911 0.000546493 0.000155707"/>
                  <body name="bucket_bottom_grip" pos=".4 0 -.85" euler="0 0 0">
                      <geom name="bucket_bottom_grip" type="box" size=".04 .8 .04" material="boom" friction="10 .35 1" condim="6"/>
                      <inertial pos="0 0 0" mass=".115" diaginertia="5.45707e-05 4.63101e-05 4.32692e-05"/>
                  </body>
              </body> <!-- Bucket -->
            </body> <!-- Arm -->
          </body> <!-- Boom -->
        </body> <!-- Chassis -->
      </body> <!-- Caterpillar -->
    </worldbody>
</mujoco>
